can@raspberrypi:~/Desktop/2025_CANSAT_FSW $ /usr/bin/python /home/can/Desktop/2025_CANSAT_FSW/can_Common/can_GPS.py
Traceback (most recent call last):
  File "/usr/lib/python3/dist-packages/serial/serialposix.py", line 322, in open
    self.fd = os.open(self.portstr, os.O_RDWR | os.O_NOCTTY | os.O_NONBLOCK)
              ^^^^^^^^^^^^^^^^^^^^^^^^^^^^^^^^^^^^^^^^^^^^^^^^^^^^^^^^^^^^^^
FileNotFoundError: [Errno 2] No such file or directory: '/dev/ttyAMA2'

During handling of the above exception, another exception occurred:

Traceback (most recent call last):
  File "/home/can/Desktop/2025_CANSAT_FSW/can_Common/can_GPS.py", line 72, in <module>
    GPS_Init()
  File "/home/can/Desktop/2025_CANSAT_FSW/can_Common/can_GPS.py", line 19, in GPS_Init
    GPS_serial = serial.Serial('/dev/ttyAMA2', baudrate=9600, parity='N', timeout=0.001)  # when connect to GPIO pins (RX: GPIO 4 TX: GPIO 5)
                 ^^^^^^^^^^^^^^^^^^^^^^^^^^^^^^^^^^^^^^^^^^^^^^^^^^^^^^^^^^^^^^^^^^^^^^^
  File "/usr/lib/python3/dist-packages/serial/serialutil.py", line 244, in __init__
    self.open()
  File "/usr/lib/python3/dist-packages/serial/serialposix.py", line 325, in open
    raise SerialException(msg.errno, "could not open port {}: {}".format(self._port, msg))
serial.serialutil.SerialException: [Errno 2] could not open port /dev/ttyAMA2: [Errno 2] No such file or directory: '/dev/ttyAMA2'
can@raspberrypi:~/Desktop/2025_CANSAT_FSW $ /usr/bin/python /home/can/Desktop/2025_CANSAT_FSW/can_Common/can_GPS.py
Traceback (most recent call last):
  File "/usr/lib/python3/dist-packages/serial/serialposix.py", line 322, in open
    self.fd = os.open(self.portstr, os.O_RDWR | os.O_NOCTTY | os.O_NONBLOCK)
              ^^^^^^^^^^^^^^^^^^^^^^^^^^^^^^^^^^^^^^^^^^^^^^^^^^^^^^^^^^^^^^
FileNotFoundError: [Errno 2] No such file or directory: '/dev/ttyAMA1'

During handling of the above exception, another exception occurred:

Traceback (most recent call last):
  File "/home/can/Desktop/2025_CANSAT_FSW/can_Common/can_GPS.py", line 72, in <module>
    GPS_Init()
  File "/home/can/Desktop/2025_CANSAT_FSW/can_Common/can_GPS.py", line 19, in GPS_Init
    GPS_serial = serial.Serial('/dev/ttyAMA1', baudrate=9600, parity='N', timeout=0.001)  # when connect to GPIO pins (RX: GPIO 4 TX: GPIO 5)
                 ^^^^^^^^^^^^^^^^^^^^^^^^^^^^^^^^^^^^^^^^^^^^^^^^^^^^^^^^^^^^^^^^^^^^^^^
  File "/usr/lib/python3/dist-packages/serial/serialutil.py", line 244, in __init__
    self.open()
  File "/usr/lib/python3/dist-packages/serial/serialposix.py", line 325, in open
    raise SerialException(msg.errno, "could not open port {}: {}".format(self._port, msg))
serial.serialutil.SerialException: [Errno 2] could not open port /dev/ttyAMA1: [Errno 2] No such file or directory: '/dev/ttyAMA1'